// PYTHON EXCEPTIONS HANDLING
	TRY
	EXCEPT
	CATCH

>>> import os
>>> 
>>> import sys
>>> sys.exc_info()
(None, None, None)
>>> 


cat exception.py 
#!/usr/bin/python

# IMPORT A MODULE
import os
import sys

# CREATE A RANDOM LIST
randomList = ['z',0,4]

# CODE
for i in randomList:
	try:
		print("The entry is: ", i)
		r = 1/int(i)
		break
	except:
		print("Oops", sys.exc_info()[0],"occured")
		print("Next Entry!!!")
print("The reciprocal of: ", i , "is", r)

O/P:

./exception.py 
('The entry is: ', 'z')
('Oops', <type 'exceptions.ValueError'>, 'occured')
Next Entry!!!
('The entry is: ', 0)
('Oops', <type 'exceptions.ZeroDivisionError'>, 'occured')
Next Entry!!!
('The entry is: ', 4)
('The reciprocal of: ', 4, 'is', 0)

// IF NO EXCEPTION OCCURS, EXCEPT BLOCK IS SKIPPED AND NORMAL FLOW CONTINUES
// BUT IF ANY EXCEPTION OCCURS, IT IS CAGHT BY THE EXCEPT BLOCK
